Workbook

Sheet Instrucciones
B2: Makers por Colombia — Registro de Donación Médica
B3: Base de datos de producción de férulas impresas en 3D
B5: Qué es este archivo
B6: • | C6: La hoja «Registro» es donde la app deposita cada producción registrada por los voluntarios.
B7: • | C7: La app envía los datos automáticamente vía Google Apps Script; no hay que escribir a mano.
B8: • | C8: «Resumen» calcula los totales solo con fórmulas: se actualiza sola a medida que llegan filas.
B9: • | C9: «Catálogo» es la lista de los 17 modelos, extraída de los proyectos 3DP Pequeña/Mediana/Grande.
B11: Cómo ponerlo en marcha
B12: 1 | C12: Súbelo a Google Drive | D12: Clic derecho → Abrir con → Google Sheets. Guarda esa copia; el .xlsx original ya no se usa.
B13: 2 | C13: Verifica el nombre de la pestaña | D13: Debe llamarse exactamente «Registro». El Apps Script busca ese nombre.
B14: 3 | C14: Pega el Apps Script | D14: Extensiones → Apps Script. El código está en la app, botón ⚙️ → Copiar.
B15: 4 | C15: Implementa como aplicación web | D15: Ejecutar como: Yo · Acceso: Cualquier persona. Copia la URL que termina en /exec.
B16: 5 | C16: Reparte la URL | D16: Cada voluntario la pega en ⚙️ dentro de la app. Desde ahí todo es automático.
B18: Diccionario de columnas de «Registro»
B19: Columna | C19: Campo | D19: Qué contiene
B20: A | C20: Fecha | D20: Fecha de la producción, formato AAAA-MM-DD.
B21: B | C21: Voluntario | D21: Nombre y apellido de quien fabricó.
B22: C | C22: Correo | D22: Correo del voluntario. Dato personal: no publicar.
B23: D | C23: Telefono | D23: Opcional. Dato personal: no publicar.
B24: E | C24: Taller | D24: Taller o makerspace.
B25: F | C25: Ciudad | D25: Ciudad del taller.
B26: G | C26: Pais | D26: País del taller.
B27: H | C27: Categoria | D27: Dedos · Mano y metacarpo · Muñeca · Antebrazo y codo · Pie · Otro.
B28: I | C28: Modelo | D28: Nombre del modelo tal como aparece en el catálogo de la app.
B29: J | C29: Archivo | D29: Nombre real del .stl. Vacío si el voluntario eligió «Otro modelo».
B30: K | C30: Variante | D30: Material, lateralidad, talla u observación libre.
... B35: P | C35: Foto | D35: Enlace de Drive. Solo la traen los modelos creados desde la app.
B37: Ejemplo de una fila bien formada
C38: Fecha | D38: 2026-08-10
C39: Voluntario | D39: Ana Restrepo
C40: Correo | D40: ana@fablab.co
C41: Telefono | D41: +57 300 123 4567
C42: Taller | D42: FabLab Medellín
C43: Ciudad | D43: Medellín
C44: Pais | D44: Colombia
C45: Categoria | D45: Mano y metacarpo
C46: Modelo | D46: FTM Grande — Izquierda
C47: Archivo | D47: FTM GRANDE IZQ(1).stl
C48: Variante | D48: PLA blanco, talla M
C49: Fabricadas | D49: 20
...

Sheet Registro
A1: Fecha | B1: Voluntario | C1: Correo | D1: Telefono | E1: Taller | F1: Ciudad | G1: Pais | H1: Categoria | I1: Modelo | J1: Archivo | K1: Variante | L1: Fabricadas | M1: Destino | N1: Notas | O1: Consentimiento | P1: Foto

Sheet Catálogo
A1: Categoría | B1: Modelo (nombre en la app) | C1: Archivo .stl | D1: Placa
A2: Dedos | B2: Fijación de dedo (V3) | C2: FIXACE PRSTU V3.stl | D2: Pequeña · Mediana
A3: Dedos | B3: Fijación de dedo completo (V2) | C3: FIXACE CELEHO PRSTU V2.stl | D3: Pequeña · Mediana
A4: Dedos | B4: Fijación pulgar–meñique (V3) | C4: FIXACE PALEC-MALIK V3.stl | D4: Pequeña · Mediana
A5: Mano y metacarpo | B5: FTM Pequeña — Soporte metacarpo | C5: FTM PEQUEÑA - Soporte Metacarpo.stl | D5: Mediana
A6: Mano y metacarpo | B6: FTM Mediana — Soporte metacarpo | C6: FTM MEDIANA - Soporte Metacarpo.stl | D6: Grande
A7: Mano y metacarpo | B7: FTM Grande — Derecha | C7: FTM GRANDE.stl | D7: Grande
A8: Mano y metacarpo | B8: FTM Grande — Izquierda | C8: FTM GRANDE IZQ(1).stl | D8: Grande
A9: Mano y metacarpo | B9: FTM — 4.º y 5.º metacarpo | C9: FTM - Mano 4toy 5to metacarpo.stl | D9: Grande
A10: Mano y metacarpo | B10: Férula Intrínseco Plus — Derecha | C10: Férula Intrinseco Plus - Derecho.stl | D10: Grande
A11: Mano y metacarpo | B11: Férula Intrínseco Plus — Izquierda | C11: Férula Intrinseco Plus - Izquierdo.stl | D11: Grande
A12: Muñeca | B12: Férula de muñeca panal (con logo) | C12: wristSplint-honeycomb-h2 logo | D12: Mediana
... A18: Pie | B18: Fijación de pie / dedo gordo (V2) | C18: FIXACE CHODIDLA - palec V2.stl | D18: Mediana

Sheet Resumen
B2: Resumen de producción
B3: Todo se calcula con fórmulas sobre la hoja «Registro». No escribas nada aquí.
B5: Fabricadas | C5: Registros | D5: Destinos | E5: Modelos | F5: Talleres
B6: =SUM(Registro!L:L) -> 0 | C6: =COUNTA(Registro!I:I)-1 -> 0 | D6: =IFERROR(SUMPRODUCT((Registro!M2:M5000<>"")/COUNTIF(Registro!M2:M5000,Registro!M2:M5000&"")),0) -> 0 | E6: =IFERROR(SUMPRODUCT((Registro!I2:I5000<>"")/COUNTIF(Registro!I2:I5000,Registro!I2:I5000&"")),0) -> 0 | F6: =IFERROR(SUMPRODUCT((Registro!E2:E5000<>"")/COUNTIF(Registro!E2:E5000,Registro!E2:E5000&"")),0) -> 0
B12: Por categoría
B13: Categoría | E13: Fabricadas
B14: Dedos | E14: =SUMIF(Registro!$H:$H,$B14,Registro!$L:$L) -> 0
B15: Mano y metacarpo | E15: =SUMIF(Registro!$H:$H,$B15,Registro!$L:$L) -> 0
B16: Muñeca | E16: =SUMIF(Registro!$H:$H,$B16,Registro!$L:$L) -> 0
B17: Antebrazo y codo | E17: =SUMIF(Registro!$H:$H,$B17,Registro!$L:$L) -> 0
B18: Pie | E18: =SUMIF(Registro!$H:$H,$B18,Registro!$L:$L) -> 0
B19: Otro | E19: =SUMIF(Registro!$H:$H,$B19,Registro!$L:$L) -> 0
B20: Total | E20: =SUM(E14:E19) -> 0
B22: Por modelo del catálogo
B23: Categoría | C23: Modelo | D23: Archivo .stl | E23: Fabricadas
B24: Dedos | C24: Fijación de dedo (V3) | D24: FIXACE PRSTU V3.stl | E24: =SUMIF(Registro!$I:$I,$C24,Registro!$L:$L) -> 0
B25: Dedos | C25: Fijación de dedo completo (V2) | D25: FIXACE CELEHO PRSTU V2.stl | E25: =SUMIF(Registro!$I:$I,$C25,Registro!$L:$L) -> 0
B26: Dedos | C26: Fijación pulgar–meñique (V3) | D26: FIXACE PALEC-MALIK V3.stl | E26: =SUMIF(Registro!$I:$I,$C26,Registro!$L:$L) -> 0
B27: Mano y metacarpo | C27: FTM Pequeña — Soporte metacarpo | D27: FTM PEQUEÑA - Soporte Metacarpo.stl | E27: =SUMIF(Registro!$I:$I,$C27,Registro!$L:$L) -> 0
B28: Mano y metacarpo | C28: FTM Mediana — Soporte metacarpo | D28: FTM MEDIANA - Soporte Metacarpo.stl | E28: =SUMIF(Registro!$I:$I,$C28,Registro!$L:$L) -> 0
B29: Mano y metacarpo | C29: FTM Grande — Derecha | D29: FTM GRANDE.stl | E29: =SUMIF(Registro!$I:$I,$C29,Registro!$L:$L) -> 0
B30: Mano y metacarpo | C30: FTM Grande — Izquierda | D30: FTM GRANDE IZQ(1).stl | E30: =SUMIF(Registro!$I:$I,$C30,Registro!$L:$L) -> 0
B31: Mano y metacarpo | C31: FTM — 4.º y 5.º metacarpo | D31: FTM - Mano 4toy 5to metacarpo.stl | E31: =SUMIF(Registro!$I:$I,$C31,Registro!$L:$L) -> 0
B32: Mano y metacarpo | C32: Férula Intrínseco Plus — Derecha | D32: Férula Intrinseco Plus - Derecho.stl | E32: =SUMIF(Registro!$I:$I,$C32,Registro!$L:$L) -> 0
B33: Mano y metacarpo | C33: Férula Intrínseco Plus — Izquierda | D33: Férula Intrinseco Plus - Izquierdo.stl | E33: =SUMIF(Registro!$I:$I,$C33,Registro!$L:$L) -> 0
B34: Muñeca | C34: Férula de muñeca panal (con logo) | D34: wristSplint-honeycomb-h2 logo | E34: =SUMIF(Registro!$I:$I,$C34,Registro!$L:$L) -> 0
B35: Antebrazo y codo | C35: Antebrazo — Braquiopalmar mediana | D35: Antebrazo - Modelo Braquiopalmar Mediana.stl | E35: =SUMIF(Registro!$I:$I,$C35,Registro!$L:$L) -> 0
... B40: Pie | C40: Fijación de pie / dedo gordo (V2) | D40: FIXACE CHODIDLA - palec V2.stl | E40: =SUMIF(Registro!$I:$I,$C40,Registro!$L:$L) -> 0
C41: Total catálogo | E41: =SUM(E24:E40) -> 0
B43: Nota: | C43: Los modelos escritos a mano («Otro modelo») no aparecen en esta tabla pero sí en «Por categoría», fila «Otro». Para desglosar por destino, taller o ciudad usa Datos → Tabla dinámica sobre la hoja «Registro».
